<?xml version="1.0"?>
<robot xmlns:xacro="http://www.ros.org/wiki/xacro" name="diff_drive_robot">

    <!-- Properties -->
    <xacro:property name="base_width" value="0.3"/>
    <xacro:property name="base_length" value="0.5"/>
    <xacro:property name="base_height" value="0.1"/>
    
    <xacro:property name="wheel_radius" value="0.1"/>
    <xacro:property name="wheel_width" value="0.05"/>
    <xacro:property name="wheel_separation" value="0.35"/>
    
    <xacro:property name="base_mass" value="5.0"/>
    <xacro:property name="wheel_mass" value="1.0"/>

    <!-- Import Gazebo customizations -->
    <xacro:include filename="$(find diff_drive_robot)/urdf/diff_drive.gazebo"/>
    
    <!-- Base Link -->
    <link name="base_footprint"/>

    <joint name="base_joint" type="fixed">
        <parent link="base_footprint"/>
        <child link="base_link"/>
        <origin xyz="0 0 ${wheel_radius}" rpy="0 0 0"/>
    </joint>

    <link name="base_link">
        <collision>
            <origin xyz="0 0 0" rpy="0 0 0"/>
            <geometry>
                <box size="${base_length} ${base_width} ${base_height}"/>
            </geometry>
        </collision>

        <visual>
            <origin xyz="0 0 0" rpy="0 0 0"/>
            <geometry>
                <box size="${base_length} ${base_width} ${base_height}"/>
            </geometry>
            <material name="blue"/>
        </visual>

        <inertial>
            <origin xyz="0 0 0" rpy="0 0 0"/>
            <mass value="${base_mass}"/>
            <inertia
                ixx="${base_mass * (base_width * base_width + base_height * base_height) / 12.0}"
                ixy="0.0"
                ixz="0.0"
                iyy="${base_mass * (base_length * base_length + base_height * base_height) / 12.0}"
                iyz="0.0"
                izz="${base_mass * (base_length * base_length + base_width * base_width) / 12.0}"/>
        </inertial>
    </link>

    <!-- Wheel Macro -->
    <xacro:macro name="wheel" params="prefix x_reflect y_reflect">
        <link name="${prefix}_wheel">
            <collision>
                <origin xyz="0 0 0" rpy="${pi/2} 0 0"/>
                <geometry>
                    <cylinder radius="${wheel_radius}" length="${wheel_width}"/>
                </geometry>
            </collision>

            <visual>
                <origin xyz="0 0 0" rpy="${pi/2} 0 0"/>
                <geometry>
                    <cylinder radius="${wheel_radius}" length="${wheel_width}"/>
                </geometry>
                <material name="black"/>
            </visual>

            <inertial>
                <origin xyz="0 0 0" rpy="${pi/2} 0 0"/>
                <mass value="${wheel_mass}"/>
                <inertia
                    ixx="${wheel_mass * (3 * wheel_radius * wheel_radius + wheel_width * wheel_width) / 12}"
                    ixy="0.0"
                    ixz="0.0"
                    iyy="${wheel_mass * (3 * wheel_radius * wheel_radius + wheel_width * wheel_width) / 12}"
                    iyz="0.0"
                    izz="${wheel_mass * wheel_radius * wheel_radius / 2}"/>
            </inertial>
        </link>

        <joint name="${prefix}_wheel_joint" type="continuous">
            <parent link="base_link"/>
            <child link="${prefix}_wheel"/>
            <origin xyz="${x_reflect*base_length/4} ${y_reflect*wheel_separation/2} 0" rpy="0 0 0"/>
            <axis xyz="0 1 0"/>
            <dynamics damping="0.1"/>
        </joint>
    </xacro:macro>

    <!-- Create wheels -->
    <xacro:wheel prefix="left" x_reflect="1" y_reflect="1" />
    <xacro:wheel prefix="right" x_reflect="1" y_reflect="-1" />

    <!-- Materials -->
    <material name="black">
        <color rgba="0 0 0 1"/>
    </material>

    <material name="blue">
        <color rgba="0 0 0.8 1"/>
    </material>

</robot>